Workbook

Sheet Start here
A1: The Mat: roster and student slips
A2: KEEP THIS FILE PRIVATE. It holds student names. The Mat class sheet holds only periods and numbers (no names): this file is the only place the two meet.
A4: This file fills itself from your master list (the file with First, Last, Period and StudentID). Setup is once; after that it is one menu click, or automatic.
A5: 1. Settings tab: paste the web address of your master list next to "Master list web address". (The tab name is already "Roster Import".)
A6: 2. Extensions > Apps Script: paste in RosterSync.gs and save. Reload this sheet: a "The Mat" menu appears. The first time you use it, Google asks you to allow it: choose your account, Advanced, Go to (project), Allow.
A7: 3. The Mat > Sync from my master list. The Roster, Numbers and New students tabs fill in. Every student gets a number in their period once, and keeps it for good (someone who leaves keeps theirs; a new student gets the next free number).
A8: 4. Slips (all): a slip for every current student. Slips (new): only students whose slip has not been printed. Print with File > Print > "Current sheet" (Letter, portrait, narrow margins, fit to width), cut on the dashed lines, then The Mat > Mark the new slips as printed.
A9: 5. The Mat > Turn on automatic daily sync, and new students appear on their own each morning; you only print their slip.
A10: 6. Named results (optional): paste your class sheet's web address in Settings, then on the Imported tab click cell A1 and choose Allow access (once).
A12: Do not type in Roster, Numbers or New students: the script writes there. Yellow cells (Settings) are the ones meant for you.
A13: Students sign in on The Mat with their school Google account and type the Period and Student number from their slip. A student who changes period gets a new number in the new period (their old one is kept); their progress follows their Google account either way.

Sheet Settings
A1: Site address printed on the slips | B1: karlmaukskoepke.github.io/AlgebraMat
A2: Class sheet web address (for Named results)
A3: Master list web address
A4: Master list tab | B4: Roster Import
A6: Paste each web address from the browser's address bar while that file is open. Yellow cells are the ones to edit. The master list needs First, Last, Period and StudentID in its first row.

Sheet Roster
A1: Name | B1: Period | C1: Student number | D1: StudentID

Sheet Numbers
A1: StudentID | B1: Period | C1: Number | D1: Name | E1: FirstSeen | F1: Printed | G1: Active

Sheet New students
A1: Name | B1: Period | C1: Student number | D1: StudentID

Sheet Slips (all)
A1: =IF(Roster!A2="","",Roster!A2) | E1: =IF(Roster!A3="","",Roster!A3)
A2: =IF(Roster!A2="","","Period "&Roster!B2&" · Student number "&Roster!C2) | E2: =IF(Roster!A3="","","Period "&Roster!B3&" · Student number "&Roster!C3)
A3: =IF(Roster!A2="","","Open: "&Settings!$B$1) | E3: =IF(Roster!A3="","","Open: "&Settings!$B$1)
A4: =IF(Roster!A2="","","Tap Sign in, type your period and number, then sign in with your school Google account.") | E4: =IF(Roster!A3="","","Tap Sign in, type your period and number, then sign in with your school Google account.")
A6: =IF(Roster!A4="","",Roster!A4) | E6: =IF(Roster!A5="","",Roster!A5)
A7: =IF(Roster!A4="","","Period "&Roster!B4&" · Student number "&Roster!C4) | E7: =IF(Roster!A5="","","Period "&Roster!B5&" · Student number "&Roster!C5)
A8: =IF(Roster!A4="","","Open: "&Settings!$B$1) | E8: =IF(Roster!A5="","","Open: "&Settings!$B$1)
A9: =IF(Roster!A4="","","Tap Sign in, type your period and number, then sign in with your school Google account.") | E9: =IF(Roster!A5="","","Tap Sign in, type your period and number, then sign in with your school Google account.")
A11: =IF(Roster!A6="","",Roster!A6) | E11: =IF(Roster!A7="","",Roster!A7)
A12: =IF(Roster!A6="","","Period "&Roster!B6&" · Student number "&Roster!C6) | E12: =IF(Roster!A7="","","Period "&Roster!B7&" · Student number "&Roster!C7)
A13: =IF(Roster!A6="","","Open: "&Settings!$B$1) | E13: =IF(Roster!A7="","","Open: "&Settings!$B$1)
A14: =IF(Roster!A6="","","Tap Sign in, type your period and number, then sign in with your school Google account.") | E14: =IF(Roster!A7="","","Tap Sign in, type your period and number, then sign in with your school Google account.")
A16: =IF(Roster!A8="","",Roster!A8) | E16: =IF(Roster!A9="","",Roster!A9)
A17: =IF(Roster!A8="","","Period "&Roster!B8&" · Student number "&Roster!C8) | E17: =IF(Roster!A9="","","Period "&Roster!B9&" · Student number "&Roster!C9)
A18: =IF(Roster!A8="","","Open: "&Settings!$B$1) | E18: =IF(Roster!A9="","","Open: "&Settings!$B$1)
A19: =IF(Roster!A8="","","Tap Sign in, type your period and number, then sign in with your school Google account.") | E19: =IF(Roster!A9="","","Tap Sign in, type your period and number, then sign in with your school Google account.")
A21: =IF(Roster!A10="","",Roster!A10) | E21: =IF(Roster!A11="","",Roster!A11)
A22: =IF(Roster!A10="","","Period "&Roster!B10&" · Student number "&Roster!C10) | E22: =IF(Roster!A11="","","Period "&Roster!B11&" · Student number "&Roster!C11)
A23: =IF(Roster!A10="","","Open: "&Settings!$B$1) | E23: =IF(Roster!A11="","","Open: "&Settings!$B$1)
A24: =IF(Roster!A10="","","Tap Sign in, type your period and number, then sign in with your school Google account.") | E24: =IF(Roster!A11="","","Tap Sign in, type your period and number, then sign in with your school Google account.")
A26: =IF(Roster!A12="","",Roster!A12) | E26: =IF(Roster!A13="","",Roster!A13)
A27: =IF(Roster!A12="","","Period "&Roster!B12&" · Student number "&Roster!C12) | E27: =IF(Roster!A13="","","Period "&Roster!B13&" · Student number "&Roster!C13)
A28: =IF(Roster!A12="","","Open: "&Settings!$B$1) | E28: =IF(Roster!A13="","","Open: "&Settings!$B$1)
A29: =IF(Roster!A12="","","Tap Sign in, type your period and number, then sign in with your school Google account.") | E29: =IF(Roster!A13="","","Tap Sign in, type your period and number, then sign in with your school Google account.")
A31: =IF(Roster!A14="","",Roster!A14) | E31: =IF(Roster!A15="","",Roster!A15)
A32: =IF(Roster!A14="","","Period "&Roster!B14&" · Student number "&Roster!C14) | E32: =IF(Roster!A15="","","Period "&Roster!B15&" · Student number "&Roster!C15)
A33: =IF(Roster!A14="","","Open: "&Settings!$B$1) | E33: =IF(Roster!A15="","","Open: "&Settings!$B$1)
A34: =IF(Roster!A14="","","Tap Sign in, type your period and number, then sign in with your school Google account.") | E34: =IF(Roster!A15="","","Tap Sign in, type your period and number, then sign in with your school Google account.")
A36: =IF(Roster!A16="","",Roster!A16) | E36: =IF(Roster!A17="","",Roster!A17)
A37: =IF(Roster!A16="","","Period "&Roster!B16&" · Student number "&Roster!C16) | E37: =IF(Roster!A17="","","Period "&Roster!B17&" · Student number "&Roster!C17)
A38: =IF(Roster!A16="","","Open: "&Settings!$B$1) | E38: =IF(Roster!A17="","","Open: "&Settings!$B$1)
A39: =IF(Roster!A16="","","Tap Sign in, type your period and number, then sign in with your school Google account.") | E39: =IF(Roster!A17="","","Tap Sign in, type your period and number, then sign in with your school Google account.")
A41: =IF(Roster!A18="","",Roster!A18) | E41: =IF(Roster!A19="","",Roster!A19)
A42: =IF(Roster!A18="","","Period "&Roster!B18&" · Student number "&Roster!C18) | E42: =IF(Roster!A19="","","Period "&Roster!B19&" · Student number "&Roster!C19)
A43: =IF(Roster!A18="","","Open: "&Settings!$B$1) | E43: =IF(Roster!A19="","","Open: "&Settings!$B$1)
A44: =IF(Roster!A18="","","Tap Sign in, type your period and number, then sign in with your school Google account.") | E44: =IF(Roster!A19="","","Tap Sign in, type your period and number, then sign in with your school Google account.")
A46: =IF(Roster!A20="","",Roster!A20) | E46: =IF(Roster!A21="","",Roster!A21)
A47: =IF(Roster!A20="","","Period "&Roster!B20&" · Student number "&Roster!C20) | E47: =IF(Roster!A21="","","Period "&Roster!B21&" · Student number "&Roster!C21)
A48: =IF(Roster!A20="","","Open: "&Settings!$B$1) | E48: =IF(Roster!A21="","","Open: "&Settings!$B$1)
A49: =IF(Roster!A20="","","Tap Sign in, type your period and number, then sign in with your school Google account.") | E49: =IF(Roster!A21="","","Tap Sign in, type your period and number, then sign in with your school Google account.")
...

Sheet Slips (new)
A1: =IF('New students'!A2="","",'New students'!A2) | E1: =IF('New students'!A3="","",'New students'!A3)
A2: =IF('New students'!A2="","","Period "&'New students'!B2&" · Student number "&'New students'!C2) | E2: =IF('New students'!A3="","","Period "&'New students'!B3&" · Student number "&'New students'!C3)
A3: =IF('New students'!A2="","","Open: "&Settings!$B$1) | E3: =IF('New students'!A3="","","Open: "&Settings!$B$1)
A4: =IF('New students'!A2="","","Tap Sign in, type your period and number, then sign in with your school Google account.") | E4: =IF('New students'!A3="","","Tap Sign in, type your period and number, then sign in with your school Google account.")
A6: =IF('New students'!A4="","",'New students'!A4) | E6: =IF('New students'!A5="","",'New students'!A5)
A7: =IF('New students'!A4="","","Period "&'New students'!B4&" · Student number "&'New students'!C4) | E7: =IF('New students'!A5="","","Period "&'New students'!B5&" · Student number "&'New students'!C5)
A8: =IF('New students'!A4="","","Open: "&Settings!$B$1) | E8: =IF('New students'!A5="","","Open: "&Settings!$B$1)
A9: =IF('New students'!A4="","","Tap Sign in, type your period and number, then sign in with your school Google account.") | E9: =IF('New students'!A5="","","Tap Sign in, type your period and number, then sign in with your school Google account.")
A11: =IF('New students'!A6="","",'New students'!A6) | E11: =IF('New students'!A7="","",'New students'!A7)
A12: =IF('New students'!A6="","","Period "&'New students'!B6&" · Student number "&'New students'!C6) | E12: =IF('New students'!A7="","","Period "&'New students'!B7&" · Student number "&'New students'!C7)
A13: =IF('New students'!A6="","","Open: "&Settings!$B$1) | E13: =IF('New students'!A7="","","Open: "&Settings!$B$1)
A14: =IF('New students'!A6="","","Tap Sign in, type your period and number, then sign in with your school Google account.") | E14: =IF('New students'!A7="","","Tap Sign in, type your period and number, then sign in with your school Google account.")
A16: =IF('New students'!A8="","",'New students'!A8) | E16: =IF('New students'!A9="","",'New students'!A9)
A17: =IF('New students'!A8="","","Period "&'New students'!B8&" · Student number "&'New students'!C8) | E17: =IF('New students'!A9="","","Period "&'New students'!B9&" · Student number "&'New students'!C9)
A18: =IF('New students'!A8="","","Open: "&Settings!$B$1) | E18: =IF('New students'!A9="","","Open: "&Settings!$B$1)
A19: =IF('New students'!A8="","","Tap Sign in, type your period and number, then sign in with your school Google account.") | E19: =IF('New students'!A9="","","Tap Sign in, type your period and number, then sign in with your school Google account.")
A21: =IF('New students'!A10="","",'New students'!A10) | E21: =IF('New students'!A11="","",'New students'!A11)
A22: =IF('New students'!A10="","","Period "&'New students'!B10&" · Student number "&'New students'!C10) | E22: =IF('New students'!A11="","","Period "&'New students'!B11&" · Student number "&'New students'!C11)
A23: =IF('New students'!A10="","","Open: "&Settings!$B$1) | E23: =IF('New students'!A11="","","Open: "&Settings!$B$1)
A24: =IF('New students'!A10="","","Tap Sign in, type your period and number, then sign in with your school Google account.") | E24: =IF('New students'!A11="","","Tap Sign in, type your period and number, then sign in with your school Google account.")
A26: =IF('New students'!A12="","",'New students'!A12) | E26: =IF('New students'!A13="","",'New students'!A13)
A27: =IF('New students'!A12="","","Period "&'New students'!B12&" · Student number "&'New students'!C12) | E27: =IF('New students'!A13="","","Period "&'New students'!B13&" · Student number "&'New students'!C13)
A28: =IF('New students'!A12="","","Open: "&Settings!$B$1) | E28: =IF('New students'!A13="","","Open: "&Settings!$B$1)
A29: =IF('New students'!A12="","","Tap Sign in, type your period and number, then sign in with your school Google account.") | E29: =IF('New students'!A13="","","Tap Sign in, type your period and number, then sign in with your school Google account.")
A31: =IF('New students'!A14="","",'New students'!A14) | E31: =IF('New students'!A15="","",'New students'!A15)
A32: =IF('New students'!A14="","","Period "&'New students'!B14&" · Student number "&'New students'!C14) | E32: =IF('New students'!A15="","","Period "&'New students'!B15&" · Student number "&'New students'!C15)
A33: =IF('New students'!A14="","","Open: "&Settings!$B$1) | E33: =IF('New students'!A15="","","Open: "&Settings!$B$1)
A34: =IF('New students'!A14="","","Tap Sign in, type your period and number, then sign in with your school Google account.") | E34: =IF('New students'!A15="","","Tap Sign in, type your period and number, then sign in with your school Google account.")
A36: =IF('New students'!A16="","",'New students'!A16) | E36: =IF('New students'!A17="","",'New students'!A17)
A37: =IF('New students'!A16="","","Period "&'New students'!B16&" · Student number "&'New students'!C16) | E37: =IF('New students'!A17="","","Period "&'New students'!B17&" · Student number "&'New students'!C17)
A38: =IF('New students'!A16="","","Open: "&Settings!$B$1) | E38: =IF('New students'!A17="","","Open: "&Settings!$B$1)
A39: =IF('New students'!A16="","","Tap Sign in, type your period and number, then sign in with your school Google account.") | E39: =IF('New students'!A17="","","Tap Sign in, type your period and number, then sign in with your school Google account.")
A41: =IF('New students'!A18="","",'New students'!A18) | E41: =IF('New students'!A19="","",'New students'!A19)
A42: =IF('New students'!A18="","","Period "&'New students'!B18&" · Student number "&'New students'!C18) | E42: =IF('New students'!A19="","","Period "&'New students'!B19&" · Student number "&'New students'!C19)
A43: =IF('New students'!A18="","","Open: "&Settings!$B$1) | E43: =IF('New students'!A19="","","Open: "&Settings!$B$1)
A44: =IF('New students'!A18="","","Tap Sign in, type your period and number, then sign in with your school Google account.") | E44: =IF('New students'!A19="","","Tap Sign in, type your period and number, then sign in with your school Google account.")
A46: =IF('New students'!A20="","",'New students'!A20) | E46: =IF('New students'!A21="","",'New students'!A21)
A47: =IF('New students'!A20="","","Period "&'New students'!B20&" · Student number "&'New students'!C20) | E47: =IF('New students'!A21="","","Period "&'New students'!B21&" · Student number "&'New students'!C21)
A48: =IF('New students'!A20="","","Open: "&Settings!$B$1) | E48: =IF('New students'!A21="","","Open: "&Settings!$B$1)
A49: =IF('New students'!A20="","","Tap Sign in, type your period and number, then sign in with your school Google account.") | E49: =IF('New students'!A21="","","Tap Sign in, type your period and number, then sign in with your school Google account.")
...

Sheet Imported
A1: =IF(Settings!B2="","",IMPORTRANGE(Settings!B2,"Summary!A1:I151")) | K1: The class sheet's Summary, copied in here (read only). Allow access on A1 the first time.

Sheet Named results
A1: Name | B1: Period | C1: Student number | D1: Levels done | E1: Problems tried | F1: Clean % | G1: Stuck presses | H1: Fluency runs
A2: =IF(Roster!A2="","",Roster!A2) | B2: =IF($A2="","",Roster!B2) | C2: =IF($A2="","",Roster!C2) | D2: =IF($A2="","",IFERROR(SUMIFS(Imported!$D$2:$D$151,Imported!$B$2:$B$151,$B2&"",Imported!$C$2:$C$151,$C2&""),0)) | E2: =IF($A2="","",IFERROR(SUMIFS(Imported!$E$2:$E$151,Imported!$B$2:$B$151,$B2&"",Imported!$C$2:$C$151,$C2&""),0)) | F2: =IF($A2="","",IFERROR(SUMIFS(Imported!$F$2:$F$151,Imported!$B$2:$B$151,$B2&"",Imported!$C$2:$C$151,$C2&""),0)) | G2: =IF($A2="","",IFERROR(SUMIFS(Imported!$G$2:$G$151,Imported!$B$2:$B$151,$B2&"",Imported!$C$2:$C$151,$C2&""),0)) | H2: =IF($A2="","",IFERROR(SUMIFS(Imported!$H$2:$H$151,Imported!$B$2:$B$151,$B2&"",Imported!$C$2:$C$151,$C2&""),0))
A3: =IF(Roster!A3="","",Roster!A3) | B3: =IF($A3="","",Roster!B3) | C3: =IF($A3="","",Roster!C3) | D3: =IF($A3="","",IFERROR(SUMIFS(Imported!$D$2:$D$151,Imported!$B$2:$B$151,$B3&"",Imported!$C$2:$C$151,$C3&""),0)) | E3: =IF($A3="","",IFERROR(SUMIFS(Imported!$E$2:$E$151,Imported!$B$2:$B$151,$B3&"",Imported!$C$2:$C$151,$C3&""),0)) | F3: =IF($A3="","",IFERROR(SUMIFS(Imported!$F$2:$F$151,Imported!$B$2:$B$151,$B3&"",Imported!$C$2:$C$151,$C3&""),0)) | G3: =IF($A3="","",IFERROR(SUMIFS(Imported!$G$2:$G$151,Imported!$B$2:$B$151,$B3&"",Imported!$C$2:$C$151,$C3&""),0)) | H3: =IF($A3="","",IFERROR(SUMIFS(Imported!$H$2:$H$151,Imported!$B$2:$B$151,$B3&"",Imported!$C$2:$C$151,$C3&""),0))
A4: =IF(Roster!A4="","",Roster!A4) | B4: =IF($A4="","",Roster!B4) | C4: =IF($A4="","",Roster!C4) | D4: =IF($A4="","",IFERROR(SUMIFS(Imported!$D$2:$D$151,Imported!$B$2:$B$151,$B4&"",Imported!$C$2:$C$151,$C4&""),0)) | E4: =IF($A4="","",IFERROR(SUMIFS(Imported!$E$2:$E$151,Imported!$B$2:$B$151,$B4&"",Imported!$C$2:$C$151,$C4&""),0)) | F4: =IF($A4="","",IFERROR(SUMIFS(Imported!$F$2:$F$151,Imported!$B$2:$B$151,$B4&"",Imported!$C$2:$C$151,$C4&""),0)) | G4: =IF($A4="","",IFERROR(SUMIFS(Imported!$G$2:$G$151,Imported!$B$2:$B$151,$B4&"",Imported!$C$2:$C$151,$C4&""),0)) | H4: =IF($A4="","",IFERROR(SUMIFS(Imported!$H$2:$H$151,Imported!$B$2:$B$151,$B4&"",Imported!$C$2:$C$151,$C4&""),0))
A5: =IF(Roster!A5="","",Roster!A5) | B5: =IF($A5="","",Roster!B5) | C5: =IF($A5="","",Roster!C5) | D5: =IF($A5="","",IFERROR(SUMIFS(Imported!$D$2:$D$151,Imported!$B$2:$B$151,$B5&"",Imported!$C$2:$C$151,$C5&""),0)) | E5: =IF($A5="","",IFERROR(SUMIFS(Imported!$E$2:$E$151,Imported!$B$2:$B$151,$B5&"",Imported!$C$2:$C$151,$C5&""),0)) | F5: =IF($A5="","",IFERROR(SUMIFS(Imported!$F$2:$F$151,Imported!$B$2:$B$151,$B5&"",Imported!$C$2:$C$151,$C5&""),0)) | G5: =IF($A5="","",IFERROR(SUMIFS(Imported!$G$2:$G$151,Imported!$B$2:$B$151,$B5&"",Imported!$C$2:$C$151,$C5&""),0)) | H5: =IF($A5="","",IFERROR(SUMIFS(Imported!$H$2:$H$151,Imported!$B$2:$B$151,$B5&"",Imported!$C$2:$C$151,$C5&""),0))
A6: =IF(Roster!A6="","",Roster!A6) | B6: =IF($A6="","",Roster!B6) | C6: =IF($A6="","",Roster!C6) | D6: =IF($A6="","",IFERROR(SUMIFS(Imported!$D$2:$D$151,Imported!$B$2:$B$151,$B6&"",Imported!$C$2:$C$151,$C6&""),0)) | E6: =IF($A6="","",IFERROR(SUMIFS(Imported!$E$2:$E$151,Imported!$B$2:$B$151,$B6&"",Imported!$C$2:$C$151,$C6&""),0)) | F6: =IF($A6="","",IFERROR(SUMIFS(Imported!$F$2:$F$151,Imported!$B$2:$B$151,$B6&"",Imported!$C$2:$C$151,$C6&""),0)) | G6: =IF($A6="","",IFERROR(SUMIFS(Imported!$G$2:$G$151,Imported!$B$2:$B$151,$B6&"",Imported!$C$2:$C$151,$C6&""),0)) | H6: =IF($A6="","",IFERROR(SUMIFS(Imported!$H$2:$H$151,Imported!$B$2:$B$151,$B6&"",Imported!$C$2:$C$151,$C6&""),0))
A7: =IF(Roster!A7="","",Roster!A7) | B7: =IF($A7="","",Roster!B7) | C7: =IF($A7="","",Roster!C7) | D7: =IF($A7="","",IFERROR(SUMIFS(Imported!$D$2:$D$151,Imported!$B$2:$B$151,$B7&"",Imported!$C$2:$C$151,$C7&""),0)) | E7: =IF($A7="","",IFERROR(SUMIFS(Imported!$E$2:$E$151,Imported!$B$2:$B$151,$B7&"",Imported!$C$2:$C$151,$C7&""),0)) | F7: =IF($A7="","",IFERROR(SUMIFS(Imported!$F$2:$F$151,Imported!$B$2:$B$151,$B7&"",Imported!$C$2:$C$151,$C7&""),0)) | G7: =IF($A7="","",IFERROR(SUMIFS(Imported!$G$2:$G$151,Imported!$B$2:$B$151,$B7&"",Imported!$C$2:$C$151,$C7&""),0)) | H7: =IF($A7="","",IFERROR(SUMIFS(Imported!$H$2:$H$151,Imported!$B$2:$B$151,$B7&"",Imported!$C$2:$C$151,$C7&""),0))
A8: =IF(Roster!A8="","",Roster!A8) | B8: =IF($A8="","",Roster!B8) | C8: =IF($A8="","",Roster!C8) | D8: =IF($A8="","",IFERROR(SUMIFS(Imported!$D$2:$D$151,Imported!$B$2:$B$151,$B8&"",Imported!$C$2:$C$151,$C8&""),0)) | E8: =IF($A8="","",IFERROR(SUMIFS(Imported!$E$2:$E$151,Imported!$B$2:$B$151,$B8&"",Imported!$C$2:$C$151,$C8&""),0)) | F8: =IF($A8="","",IFERROR(SUMIFS(Imported!$F$2:$F$151,Imported!$B$2:$B$151,$B8&"",Imported!$C$2:$C$151,$C8&""),0)) | G8: =IF($A8="","",IFERROR(SUMIFS(Imported!$G$2:$G$151,Imported!$B$2:$B$151,$B8&"",Imported!$C$2:$C$151,$C8&""),0)) | H8: =IF($A8="","",IFERROR(SUMIFS(Imported!$H$2:$H$151,Imported!$B$2:$B$151,$B8&"",Imported!$C$2:$C$151,$C8&""),0))
A9: =IF(Roster!A9="","",Roster!A9) | B9: =IF($A9="","",Roster!B9) | C9: =IF($A9="","",Roster!C9) | D9: =IF($A9="","",IFERROR(SUMIFS(Imported!$D$2:$D$151,Imported!$B$2:$B$151,$B9&"",Imported!$C$2:$C$151,$C9&""),0)) | E9: =IF($A9="","",IFERROR(SUMIFS(Imported!$E$2:$E$151,Imported!$B$2:$B$151,$B9&"",Imported!$C$2:$C$151,$C9&""),0)) | F9: =IF($A9="","",IFERROR(SUMIFS(Imported!$F$2:$F$151,Imported!$B$2:$B$151,$B9&"",Imported!$C$2:$C$151,$C9&""),0)) | G9: =IF($A9="","",IFERROR(SUMIFS(Imported!$G$2:$G$151,Imported!$B$2:$B$151,$B9&"",Imported!$C$2:$C$151,$C9&""),0)) | H9: =IF($A9="","",IFERROR(SUMIFS(Imported!$H$2:$H$151,Imported!$B$2:$B$151,$B9&"",Imported!$C$2:$C$151,$C9&""),0))
A10: =IF(Roster!A10="","",Roster!A10) | B10: =IF($A10="","",Roster!B10) | C10: =IF($A10="","",Roster!C10) | D10: =IF($A10="","",IFERROR(SUMIFS(Imported!$D$2:$D$151,Imported!$B$2:$B$151,$B10&"",Imported!$C$2:$C$151,$C10&""),0)) | E10: =IF($A10="","",IFERROR(SUMIFS(Imported!$E$2:$E$151,Imported!$B$2:$B$151,$B10&"",Imported!$C$2:$C$151,$C10&""),0)) | F10: =IF($A10="","",IFERROR(SUMIFS(Imported!$F$2:$F$151,Imported!$B$2:$B$151,$B10&"",Imported!$C$2:$C$151,$C10&""),0)) | G10: =IF($A10="","",IFERROR(SUMIFS(Imported!$G$2:$G$151,Imported!$B$2:$B$151,$B10&"",Imported!$C$2:$C$151,$C10&""),0)) | H10: =IF($A10="","",IFERROR(SUMIFS(Imported!$H$2:$H$151,Imported!$B$2:$B$151,$B10&"",Imported!$C$2:$C$151,$C10&""),0))
A11: =IF(Roster!A11="","",Roster!A11) | B11: =IF($A11="","",Roster!B11) | C11: =IF($A11="","",Roster!C11) | D11: =IF($A11="","",IFERROR(SUMIFS(Imported!$D$2:$D$151,Imported!$B$2:$B$151,$B11&"",Imported!$C$2:$C$151,$C11&""),0)) | E11: =IF($A11="","",IFERROR(SUMIFS(Imported!$E$2:$E$151,Imported!$B$2:$B$151,$B11&"",Imported!$C$2:$C$151,$C11&""),0)) | F11: =IF($A11="","",IFERROR(SUMIFS(Imported!$F$2:$F$151,Imported!$B$2:$B$151,$B11&"",Imported!$C$2:$C$151,$C11&""),0)) | G11: =IF($A11="","",IFERROR(SUMIFS(Imported!$G$2:$G$151,Imported!$B$2:$B$151,$B11&"",Imported!$C$2:$C$151,$C11&""),0)) | H11: =IF($A11="","",IFERROR(SUMIFS(Imported!$H$2:$H$151,Imported!$B$2:$B$151,$B11&"",Imported!$C$2:$C$151,$C11&""),0))
A12: =IF(Roster!A12="","",Roster!A12) | B12: =IF($A12="","",Roster!B12) | C12: =IF($A12="","",Roster!C12) | D12: =IF($A12="","",IFERROR(SUMIFS(Imported!$D$2:$D$151,Imported!$B$2:$B$151,$B12&"",Imported!$C$2:$C$151,$C12&""),0)) | E12: =IF($A12="","",IFERROR(SUMIFS(Imported!$E$2:$E$151,Imported!$B$2:$B$151,$B12&"",Imported!$C$2:$C$151,$C12&""),0)) | F12: =IF($A12="","",IFERROR(SUMIFS(Imported!$F$2:$F$151,Imported!$B$2:$B$151,$B12&"",Imported!$C$2:$C$151,$C12&""),0)) | G12: =IF($A12="","",IFERROR(SUMIFS(Imported!$G$2:$G$151,Imported!$B$2:$B$151,$B12&"",Imported!$C$2:$C$151,$C12&""),0)) | H12: =IF($A12="","",IFERROR(SUMIFS(Imported!$H$2:$H$151,Imported!$B$2:$B$151,$B12&"",Imported!$C$2:$C$151,$C12&""),0))
A13: =IF(Roster!A13="","",Roster!A13) | B13: =IF($A13="","",Roster!B13) | C13: =IF($A13="","",Roster!C13) | D13: =IF($A13="","",IFERROR(SUMIFS(Imported!$D$2:$D$151,Imported!$B$2:$B$151,$B13&"",Imported!$C$2:$C$151,$C13&""),0)) | E13: =IF($A13="","",IFERROR(SUMIFS(Imported!$E$2:$E$151,Imported!$B$2:$B$151,$B13&"",Imported!$C$2:$C$151,$C13&""),0)) | F13: =IF($A13="","",IFERROR(SUMIFS(Imported!$F$2:$F$151,Imported!$B$2:$B$151,$B13&"",Imported!$C$2:$C$151,$C13&""),0)) | G13: =IF($A13="","",IFERROR(SUMIFS(Imported!$G$2:$G$151,Imported!$B$2:$B$151,$B13&"",Imported!$C$2:$C$151,$C13&""),0)) | H13: =IF($A13="","",IFERROR(SUMIFS(Imported!$H$2:$H$151,Imported!$B$2:$B$151,$B13&"",Imported!$C$2:$C$151,$C13&""),0))
... A151: =IF(Roster!A151="","",Roster!A151) | B151: =IF($A151="","",Roster!B151) | C151: =IF($A151="","",Roster!C151) | D151: =IF($A151="","",IFERROR(SUMIFS(Imported!$D$2:$D$151,Imported!$B$2:$B$151,$B151&"",Imported!$C$2:$C$151,$C151&""),0)) | E151: =IF($A151="","",IFERROR(SUMIFS(Imported!$E$2:$E$151,Imported!$B$2:$B$151,$B151&"",Imported!$C$2:$C$151,$C151&""),0)) | F151: =IF($A151="","",IFERROR(SUMIFS(Imported!$F$2:$F$151,Imported!$B$2:$B$151,$B151&"",Imported!$C$2:$C$151,$C151&""),0)) | G151: =IF($A151="","",IFERROR(SUMIFS(Imported!$G$2:$G$151,Imported!$B$2:$B$151,$B151&"",Imported!$C$2:$C$151,$C151&""),0)) | H151: =IF($A151="","",IFERROR(SUMIFS(Imported!$H$2:$H$151,Imported!$B$2:$B$151,$B151&"",Imported!$C$2:$C$151,$C151&""),0))
